Workbook

Sheet README
A1: Board A — Directors (Guber-style)
A2: This workbook is a living “lay of the land” board for working directors: lane/scale/tonal DNA, track record, and near-term commitments.
A4: How to use
A5: 1) Start in UNIVERSE to get the real lay of the land (400+ working directors). Filter by Tier/Lane/Scale. 2) Use DIRECTORS for deeper vetted profiles (your “Board A” shortlist). 3) PROJECTS_NEXT is a flat list of announced upcoming projects (use it to sanity-check availability). 4) ACTOR_MATRIX helps you map actor↔director repeat relationships. 5) DASHBOARD gives quick counts (DIRECTORS + UNIVERSE).
A6: New fields (2026-01-29 update) • Budget bands: use BudgetBandTypical (+ optional low/high) to bucket directors by the budget range they can credibly carry. • Last-3 performance: Film1–Film3 columns capture the last 3 director credits with Domestic/International/Worldwide grosses (source: The Numbers). Populate TheNumbersURL first, then fill/refresh the numbers. • AVAILABILITY sheet is a dedicated “pegboard” view to track current/next commitments + confidence.
A7: Truth-seeking rules
A8: • Every row should have at least 1–3 source links. • Use 'Last Verified' to track staleness; refresh anything older than ~90 days. • Treat availability as probabilistic (use AvailabilityConf).
A10: Tier guide (editable)
A11: T0 = global event / tentpole proven; T1 = bankable studio event; T2 = established studio/prestige/genre; T3 = workman (reliable hired-gun, lane-specific); T4 = indie/specialty; T5 = emerging/breakout.
A13: Notes on sensitive fields
A14: This version avoids rumor/hush-hush “politics” and only uses publicly reported info. Add internal intel in a separate private copy.
A16: Last updated
A17: 2026-01-29

Sheet DIRECTORS
A1: Director | B1: Tier | C1: CareerPhase | D1: PrimaryLane | E1: SecondaryLanes | F1: ScaleProven | G1: TonalDNA | H1: Last3Features | I1: LastFilm | J1: LastFilmYear | K1: LastFilmType | L1: LastFilmBudgetUSD | M1: LastFilmWWGrossUSD | N1: NextProject | O1: NextRelease | P1: NextStatus | Q1: Availability | R1: AvailabilityConf | S1: ActorMagnet | T1: RecentActors | U1: RepeatCollabs | V1: PackagingNotes | W1: OpsNotes | X1: LastVerified | Y1: Source1 | Z1: Source2 | AA1: Source3 | AB1: TheNumbersURL | AC1: Last3_Source | AD1: Film1_Title | AE1: Film1_ReleaseDate | AF1: Film1_DomesticGrossUSD | AG1: Film1_IntlGrossUSD | AH1: Film1_WWGrossUSD | AI1: Film2_Title | AJ1: Film2_ReleaseDate | AK1: Film2_DomesticGrossUSD | AL1: Film2_IntlGrossUSD | AM1: Film2_WWGrossUSD | AN1: Film3_Title | AO1: Film3_ReleaseDate | AP1: Film3_DomesticGrossUSD | AQ1: Film3_IntlGrossUSD | AR1: Film3_WWGrossUSD | AS1: BudgetBandTypical | AT1: BudgetBandLowUSD | AU1: BudgetBandHighUSD
A2: Christopher Nolan | B2: T0 | C2: Peak (Event filmmaker) | D2: Epic drama / high-concept spectacle | E2: Historical, thriller | F2: $100M–$250M+ | G2: Precision, IMAX spectacle, time/structure games | H2: Oppenheimer (2023); Tenet (2020); Dunkirk (2017) | I2: Oppenheimer | J2: 2023 | K2: Theatrical | L2: ~$100M | M2: 976757255 | N2: The Odyssey | O2: Jul 17, 2026 (US theatrical) | P2: Post-production/announced release | Q2: Late 2026+ (post-release) | R2: Med | S2: 5 | T2: Cillian Murphy; Matt Damon; Emily Blunt; Robert Downey Jr.; Florence Pugh | U2: Emma Thomas (prod); Hoyte van Hoytema (DP); Ludwig Göransson (music) | V2: Can attract A-list and premium formats; schedule locked to July 2026 release. | W2: Long prep/post; prefers high control and specific formats. | X2: 46051 | Y2: https://en.wikipedia.org/wiki/Oppenheimer_(film) | Z2: https://en.wikipedia.org/wiki/The_Odyssey_(2026_film) | AB2: https://www.the-numbers.com/person/106410401-Christopher-Nolan | AC2: The Numbers | AD2: Oppenheimer | AE2: Jul 21, 2023 | AF2: 330078895 | AG2: 646678360 | AH2: 976757255 | AI2: Tenet | AJ2: Sep 3, 2020 | AK2: 59473550 | AL2: 306800000 | AM2: 366273550 | AN2: Dunkirk | AO2: Jul 21, 2017 | AP2: 190068280 | AQ2: 338000000 | AR2: 528068280 | AT2: =IFERROR(VLOOKUP(AS2,BUDGET_BANDS!$A$2:$C$9,2,FALSE),"") | AU2: =IFERROR(VLOOKUP(AS2,BUDGET_BANDS!$A$2:$C$9,3,FALSE),"")
A3: Denis Villeneuve | B3: T0 | C3: Peak (Prestige + tentpole) | D3: Sci-fi / epic worldbuilding | E3: Thriller, drama | F3: $100M–$200M+ | G3: Atmospheric, austere, grounded scale | H3: Dune: Part Two (2024); Dune (2021); Blade Runner 2049 (2017) | I3: Dune: Part Two | J3: 2024 | K3: Theatrical | L3: $190M | M3: 715206195 | N3: James Bond (next film) / Dune: Part Three | O3: Bond: TBA; Dune 3: Dec 18, 2026 | P3: Announced / in development | Q3: Very limited 2025–2026 (Bond/Dune pipeline) | R3: Med | S3: 5 | T3: Timothée Chalamet; Zendaya; Rebecca Ferguson; Josh Brolin; Javier Bardem | U3: Greig Fraser (DP); Hans Zimmer (music, past); Legendary/WB (Dune) | V3: Bankable for elevated sci-fi/action; high studio alignment; schedule likely locked. | W3: Large-scale VFX and long post cycles common. | X3: 46051 | Y3: https://en.wikipedia.org/wiki/Dune:_Part_Two | Z3: https://deadline.com/2025/06/denis-villeneuve-direct-next-james-bond-film-1236444861/ | AA3: https://en.wikipedia.org/wiki/Dune:_Part_Three | AB3: https://www.the-numbers.com/person/447440401-Denis-Villeneuve | AC3: The Numbers | AD3: Dune: Part Two | AE3: Mar 1, 2024 | AF3: 282709065 | AG3: 432497130 | AH3: 715206195 | AI3: Dune | AJ3: Oct 22, 2021 | AK3: 111031267 | AL3: 318518799 | AM3: 429550066 | AN3: Blade Runner 2049 | AO3: Oct 6, 2017 | AP3: 92054159 | AQ3: 167100000 | AR3: 259154159 | AT3: =IFERROR(VLOOKUP(AS3,BUDGET_BANDS!$A$2:$C$9,2,FALSE),"") | AU3: =IFERROR(VLOOKUP(AS3,BUDGET_BANDS!$A$2:$C$9,3,FALSE),"")
A4: Greta Gerwig | B4: T0 | C4: Peak (IP + auteur) | D4: Comedy/drama with strong voice; IP reinvention | E4: Fantasy | F4: $50M–$200M | G4: Character-forward, witty, empathetic | H4: Barbie (2023); Little Women (2019); Lady Bird (2017) | I4: Barbie | J4: 2023 | K4: Theatrical | L4: $128–145M | M4: 1447685476 | N4: Narnia: The Magician's Nephew | O4: Nov 26, 2026 (theatrical) / Dec 25 (Netflix) | P4: Announced / pre-production | Q4: Likely unavailable through 2026 (Narnia) | R4: Med | S4: 5 | T4: Margot Robbie; Ryan Gosling; America Ferrera; Emma Mackey; Daniel Craig | U4: Noah Baumbach (writing, past); Amy Pascal (prod, Narnia) | V4: Strong actor/brand magnet; lanes beyond comedy now include big fantasy. | W4: Likely high creative control; talent-heavy ensembles. | X4: 46051 | Y4: https://en.wikipedia.org/wiki/Barbie_(film) | Z4: https://en.wikipedia.org/wiki/Narnia:_The_Magician%27s_Nephew | AA4: https://www.netflix.com/tudum/articles/narnia-release-date | AB4: https://www.the-numbers.com/person/54050401-Greta-Gerwig | AC4: The Numbers | AD4: Barbie | AE4: Jul 21, 2023 | AF4: 636785476 | AG4: 810900000 | AH4: 1447685476 | AI4: Little Women | AJ4: Dec 25, 2019 | AK4: 108095955 | AL4: 110742431 | AM4: 218838386 | AN4: Lady Bird | AO4: Nov 3, 2017 | AP4: 48958273 | AQ4: 31150209 | AR4: 80108482 | AT4: =IFERROR(VLOOKUP(AS4,BUDGET_BANDS!$A$2:$C$9,2,FALSE),"") | AU4: =IFERROR(VLOOKUP(AS4,BUDGET_BANDS!$A$2:$C$9,3,FALSE),"")
A5: Ryan Coogler | B5: T1 | C5: Peak (franchise + original) | D5: Event genre + grounded drama | E5: Action, horror | F5: $50M–$200M | G5: Emotional intensity, cultural specificity, spectacle | H5: Sinners (2025); Black Panther: Wakanda Forever (2022); Black Panther (2018) | I5: Sinners | J5: 2025 | K5: Theatrical | L5: $90–100M | M5: 368389491 | N5: Black Panther 3 | O5: TBA | P5: Confirmed next film (announced) | Q5: Likely limited while BP3 ramps | R5: Med | S5: 5 | T5: Michael B. Jordan; Hailee Steinfeld; Delroy Lindo; Letitia Wright | U5: Ludwig Göransson (music); Proximity Media; Michael B. Jordan (frequent) | V5: Can package A-list and move studio financing; strong original credibility post-Sinners. | W5: Often multi-hyphen (writer/director/producer). | X5: 46051 | Y5: https://en.wikipedia.org/wiki/Sinners_(2025_film) | Z5: https://deadline.com/2025/11/ryan-coogler-black-panther-3-next-movie-1236618702/ | AA5: https://www.the-numbers.com/movie/Sinners-%282025%29 | AB5: https://www.the-numbers.com/person/339010401-Ryan-Coogler | AC5: The Numbers | AD5: Sinners | AE5: Apr 18, 2025 | AF5: 279989632 | AG5: 88399859 | AH5: 368389491 | AI5: Black Panther: Wakanda Forever | AJ5: Nov 11, 2022 | AK5: 453829060 | AL5: 405379776 | AM5: 859208836 | AN5: Black Panther | AO5: Feb 16, 2018 | AP5: 700059566 | AQ5: 634097516 | AR5: 1334157082 | AT5: =IFERROR(VLOOKUP(AS5,BUDGET_BANDS!$A$2:$C$9,2,FALSE),"") | AU5: =IFERROR(VLOOKUP(AS5,BUDGET_BANDS!$A$2:$C$9,3,FALSE),"")
A6: James Gunn | B6: T0 | C6: Peak (franchise architect + director) | D6: Superhero / big ensemble action-comedy | E6: Genre comedy | F6: $150M–$225M+ | G6: Heart + humor, weirdness, ensemble dynamics | H6: Superman (2025); Guardians of the Galaxy Vol 3 (2023); The Suicide Squad (2021) | I6: Superman | J6: 2025 | K6: Theatrical | L6: $225M | M6: 616823803 | N6: Man of Tomorrow (Super-Family follow-up) | O6: 2027 (announced); shoots ~Apr 2026 (reported) | P6: Announced / in development | Q6: Not available (DCU duties + 2026 shoot) | R6: High | S6: 5 | T6: David Corenswet; Rachel Brosnahan; Nicholas Hoult; Jason Momoa (DCU) | U6: Peter Safran (prod); DC Studios slate | V6: Extremely strong studio leverage; schedule largely committed. | W6: Runs studio + directs—availability is the bottleneck. | X6: 46051 | Y6: https://en.wikipedia.org/wiki/Superman_(2025_film) | Z6: https://variety.com/2025/film/news/superman-sequel-man-of-tomorrow-lex-luthor-team-up-1236514155/ | AA6: https://www.hollywoodreporter.com/movies/movie-news/superman-man-of-tomorrow-sequel-plot-filming-start-1236367993/ | AB6: https://www.the-numbers.com/person/59460401-James-Gunn | AC6: The Numbers | AD6: Superman | AE6: Jul 11, 2025 | AF6: 354223803 | AG6: 262600000 | AH6: 616823803 | AI6: Guardians of the Galaxy Vol 3 | AJ6: May 5, 2023 | AK6: 358995815 | AL6: 486559962 | AM6: 845555777 | AN6: The Suicide Squad | AO6: Aug 5, 2021 | AP6: 55817425 | AQ6: 112900000 | AR6: 168717425 | AT6: =IFERROR(VLOOKUP(AS6,BUDGET_BANDS!$A$2:$C$9,2,FALSE),"") | AU6: =IFERROR(VLOOKUP(AS6,BUDGET_BANDS!$A$2:$C$9,3,FALSE),"")
A7: Matt Reeves | B7: T0 | C7: Peak (franchise + auteur) | D7: Dark franchise thriller | E7: Sci-fi, drama | F7: $100M–$200M | G7: Noir mood, grounded intensity | H7: The Batman (2022); War for the Planet of the Apes (2017); Dawn of the Planet of the Apes (2014) | I7: The Batman | J7: 2022 | K7: Theatrical | L7: ~$185–200M | M7: $772.3M | N7: The Batman: Part II | O7: Oct 1, 2027 | P7: Announced; filming spring 2026 (reported) | Q7: Limited (prep/production 2026) | R7: High | S7: 4 | T7: Robert Pattinson; Zoë Kravitz; Paul Dano; Colin Farrell | U7: Dylan Clark (prod); WB/DC | V7: Strong tonal franchise; likely unavailable through production. | W7: Long dev cycles; careful worldbuilding. | X7: 46051 | Y7: https://en.wikipedia.org/wiki/The_Batman_(film) | Z7: https://variety.com/2025/film/news/the-batman-2-filming-spring-2026-1236481330/ | AA7: https://www.imdb.com/title/tt19850008/ | AT7: =IFERROR(VLOOKUP(AS7,BUDGET_BANDS!$A$2:$C$9,2,FALSE),"") | AU7: =IFERROR(VLOOKUP(AS7,BUDGET_BANDS!$A$2:$C$9,3,FALSE),"")
A8: Christopher McQuarrie | B8: T1 | C8: Peak (action specialist) | D8: High-end action / spy | E8: Thriller | F8: $150M–$400M | G8: Practical stunt spectacle, precision pacing | H8: Mission: Impossible – The Final Reckoning (2025); Dead Reckoning (2023); Fallout (2018) | I8: Mission: Impossible – The Final Reckoning | J8: 2025 | K8: Theatrical | L8: $300–400M | M8: $598.8M | N8: (TBA) likely action package(s) | P8: TBD | Q8: Unknown / likely selective | R8: Low | S8: 4 | T8: Tom Cruise; Hayley Atwell; Simon Pegg; Ving Rhames | U8: Tom Cruise (prod/star); Skydance/Paramount (MI) | V8: Elite action credibility; availability depends on next Cruise/Paramount commitments. | W8: Complex stunts can extend schedules. | X8: 46051 | Y8: https://en.wikipedia.org/wiki/Mission:_Impossible_%E2%80%93_The_Final_Reckoning | AT8: =IFERROR(VLOOKUP(AS8,BUDGET_BANDS!$A$2:$C$9,2,FALSE),"") | AU8: =IFERROR(VLOOKUP(AS8,BUDGET_BANDS!$A$2:$C$9,3,FALSE),"")
A9: Chad Stahelski | B9: T1 | C9: Peak (action franchise builder) | D9: Action (stunt-driven) | E9: Thriller | F9: $50M–$120M+ | G9: Choreography-forward, clean mythic action | H9: John Wick: Chapter 4 (2023); John Wick: Chapter 3 (2019); John Wick: Chapter 2 (2017) | I9: John Wick: Chapter 4 | J9: 2023 | K9: Theatrical | L9: $100M | M9: $447.3M | N9: Highlander | O9: TBA | P9: Announced / in development | Q9: Limited (development for Highlander; possible JW commitments) | R9: Med | S9: 3 | T9: Keanu Reeves; Bill Skarsgård; Donnie Yen; Henry Cavill (Highlander announced cast) | U9: 87Eleven; Lionsgate (Wick) | V9: Great for action lane matching; tends toward long prep for choreography. | W9: Action-heavy prep, stunt safety, extended unit work. | X9: 46051 | Y9: https://en.wikipedia.org/wiki/John_Wick:_Chapter_4 | Z9: https://en.wikipedia.org/wiki/Highlander_(upcoming_film) | AA9: https://variety.com/2025/film/news/highlander-first-look-henry-cavill-1236295260/ | AT9: =IFERROR(VLOOKUP(AS9,BUDGET_BANDS!$A$2:$C$9,2,FALSE),"") | AU9: =IFERROR(VLOOKUP(AS9,BUDGET_BANDS!$A$2:$C$9,3,FALSE),"")
A10: David Leitch | B10: T1 | C10: Hot (studio action-comedy) | D10: Action-comedy | E10: Thriller | F10: $80M–$150M | G10: Stunts + humor, pop energy | H10: The Fall Guy (2024); Bullet Train (2022); Hobbs & Shaw (2019) | I10: The Fall Guy | J10: 2024 | K10: Theatrical | L10: $125–150M | M10: $181M | N10: How to Rob a Bank | O10: 2026 (announced) | P10: In development | Q10: Maybe late 2026 (depending on schedule) | R10: Low | S10: 4 | T10: Ryan Gosling; Emily Blunt; Brad Pitt (past); Aaron Taylor-Johnson | U10: Kelly McCormick (prod); 87North | V10: Good for action+comedy scripts; can attract major stars. | W10: High stunt needs; can run parallel units. | X10: 46051 | Y10: https://en.wikipedia.org/wiki/The_Fall_Guy_(2024_film) | Z10: https://en.wikipedia.org/wiki/How_to_Rob_a_Bank_(film) | AT10: =IFERROR(VLOOKUP(AS10,BUDGET_BANDS!$A$2:$C$9,2,FALSE),"") | AU10: =IFERROR(VLOOKUP(AS10,BUDGET_BANDS!$A$2:$C$9,3,FALSE),"")
A11: Joseph Kosinski | B11: T1 | C11: Hot (premium commercial) | D11: High-end commercial spectacle | E11: Sci-fi | F11: $150M–$300M | G11: Sleek realism, technical setpieces | H11: F1 (2025); Top Gun: Maverick (2022); Oblivion (2013) | I11: F1 (F1: The Movie) | J11: 2025 | K11: Theatrical | L11: $200–300M | M11: $631.5M | N11: Untitled UFO conspiracy thriller (Apple) | O11: TBA | P11: Package landed at Apple (announced) | Q11: Unknown (development) | R11: Low | S11: 4 | T11: Brad Pitt; Javier Bardem; Damson Idris; Kerry Condon | U11: Jerry Bruckheimer (prod); Apple Original Films | V11: Strong for big-scale thrills; tends to require technical prep. | W11: Complex production logistics; premium format pipelines. | X11: 46051 | Y11: https://en.wikipedia.org/wiki/F1_(film) | Z11: https://deadline.com/2025/03/apple-joseph-kosinski-jerry-bruckheimer-1236347695/ | AA11: https://www.the-numbers.com/movie/F1-The-Movie-%282025%29 | AT11: =IFERROR(VLOOKUP(AS11,BUDGET_BANDS!$A$2:$C$9,2,FALSE),"") | AU11: =IFERROR(VLOOKUP(AS11,BUDGET_BANDS!$A$2:$C$9,3,FALSE),"")
A12: Jordan Peele | B12: T1 | C12: Selective (event horror auteur) | D12: Social horror / thriller | E12: Sci-fi | F12: $10M–$70M | G12: High concept, uneasy humor, thematic metaphor | H12: Nope (2022); Us (2019); Get Out (2017) | I12: Nope | J12: 2022 | K12: Theatrical | L12: $68M | M12: $171.1M | N12: Untitled next feature (Universal) – release date removed | O12: TBA | P12: In development | Q12: Unknown; not locked to a public date | R12: Low | S12: 4 | T12: Daniel Kaluuya; Keke Palmer; Steven Yeun | U12: Monkeypaw Productions; Michael Abels (music) | V12: High-value attachment for horror/thriller; scarcity increases leverage. | W12: Typically original scripts with secrecy; controlled info flow. | X12: 46051 | Y12: https://en.wikipedia.org/wiki/Nope_(film) | Z12: https://variety.com/2025/film/news/jordan-peele-new-movie-removed-2026-release-date-1236505383/ | AT12: =IFERROR(VLOOKUP(AS12,BUDGET_BANDS!$A$2:$C$9,2,FALSE),"") | AU12: =IFERROR(VLOOKUP(AS12,BUDGET_BANDS!$A$2:$C$9,3,FALSE),"")
A13: James Wan | B13: T1 | C13: Established (franchise horror + superhero) | D13: Horror / supernatural | E13: Superhero action | F13: $20M–$215M | G13: Tension craft, genre mechanics | H13: Aquaman and the Lost Kingdom (2023); Malignant (2021); Aquaman (2018) | I13: Aquaman and the Lost Kingdom | J13: 2023 | K13: Theatrical | L13: $205–215M | M13: 440181226 | N13: TBD (producer-heavy slate) | P13: TBD | Q13: Unknown | R13: Low | S13: 3 | T13: Jason Momoa; Patrick Wilson; Yahya Abdul-Mateen II; Nicole Kidman | U13: Atomic Monster; Peter Safran (past DC); horror franchises | V13: Strong for horror lane; director availability uncertain. | W13: Often producing multiple projects concurrently. | X13: 46051 | Y13: https://en.wikipedia.org/wiki/Aquaman_and_the_Lost_Kingdom | AB13: https://www.the-numbers.com/person/148690401-James-Wan | AC13: The Numbers | AD13: Aquaman and the Lost Kingdom | AE13: Dec 22, 2023 | AF13: 124481226 | AG13: 315700000 | AH13: 440181226 | AI13: Malignant | AJ13: Sep 10, 2021 | AK13: 13391791 | AL13: 21500000 | AM13: 34891791 | AN13: Aquaman | AO13: Dec 21, 2018 | AP13: 335061807 | AQ13: 813800000 | AR13: 1148861807 | AT13: =IFERROR(VLOOKUP(AS13,BUDGET_BANDS!$A$2:$C$9,2,FALSE),"") | AU13: =IFERROR(VLOOKUP(AS13,BUDGET_BANDS!$A$2:$C$9,3,FALSE),"")
A14: Ari Aster | B14: T2 | C14: Hot (auteur to studio) | D14: Elevated horror | E14: Dark comedy, drama | F14: $10M–$60M | G14: Anxiety, dread, surreal humor | H14: Eddington (2025); Beau Is Afraid (2023); Midsommar (2019) | I14: Eddington | J14: 2025 | K14: Theatrical (limited) | L14: $30–35M | M14: $13.7M | N14: TBA | P14: TBD | Q14: Unknown | R14: Low | S14: 4 | T14: Joaquin Phoenix; Pedro Pascal; Emma Stone; Austin Butler | U14: A24 (past); Square Peg (prod) | V14: Strong tone setter; actor interest high but commercially variable. | W14: Can push into longer shoots for complex tone work. | X14: 46051 | Y14: https://en.wikipedia.org/wiki/Eddington_(film) | AT14: =IFERROR(VLOOKUP(AS14,BUDGET_BANDS!$A$2:$C$9,2,FALSE),"") | AU14: =IFERROR(VLOOKUP(AS14,BUDGET_BANDS!$A$2:$C$9,3,FALSE),"")
A15: Robert Eggers | B15: T2 | C15: Hot (prestige horror) | D15: Period horror | E15: Mythic drama | F15: $10M–$60M | G15: Period authenticity, gothic atmosphere | H15: Nosferatu (2024); The Northman (2022); The Lighthouse (2019) | I15: Nosferatu | J15: 2024 | K15: Theatrical | L15: $50M | M15: $181.8M | N15: Werwulf | O15: Dec 25, 2026 | P15: Announced | Q15: Limited through 2026 (Werwulf) | R15: Med | S15: 3 | T15: Bill Skarsgård; Nicholas Hoult; Lily-Rose Depp; Willem Dafoe; Aaron Taylor-Johnson | U15: Jarin Blaschke (DP); Willem Dafoe (repeat) | V15: Great for period/horror; reliable for lane match. | W15: Period builds/costumes; specialized dialect work. | X15: 46051 | Y15: https://en.wikipedia.org/wiki/Nosferatu_(2024_film) | Z15: https://en.wikipedia.org/wiki/Werwulf | AT15: =IFERROR(VLOOKUP(AS15,BUDGET_BANDS!$A$2:$C$9,2,FALSE),"") | AU15: =IFERROR(VLOOKUP(AS15,BUDGET_BANDS!$A$2:$C$9,3,FALSE),"")
A16: Yorgos Lanthimos | B16: T2 | C16: Peak (prestige + stars) | D16: Dark comedy / prestige drama | E16: Thriller | F16: $20M–$60M | G16: Absurdist, deadpan, stylized | H16: Bugonia (2025); Poor Things (2023); The Favourite (2018) | I16: Bugonia | J16: 2025 | K16: Theatrical | L16: $45–55M | M16: $41.6M | N16: TBA | P16: TBD | Q16: Unknown | R16: Low | S16: 4 | T16: Emma Stone; Jesse Plemons; Mark Ruffalo; Willem Dafoe | U16: Emma Stone (repeat); Robbie Ryan (DP); Element Pictures | V16: Star-friendly prestige lane; unique tone can polarize. | W16: Stylized performance requirements. | X16: 46051 | Y16: https://en.wikipedia.org/wiki/Bugonia_(film) | Z16: https://en.wikipedia.org/wiki/Poor_Things_(film) | AT16: =IFERROR(VLOOKUP(AS16,BUDGET_BANDS!$A$2:$C$9,2,FALSE),"") | AU16: =IFERROR(VLOOKUP(AS16,BUDGET_BANDS!$A$2:$C$9,3,FALSE),"")
A17: Damien Chazelle | B17: T2 | C17: Rebuild/next swing | D17: Music/artist drama | E17: Period, thriller | F17: $20M–$80M | G17: Kinetic, romantic, big setpieces | H17: Babylon (2022); First Man (2018); La La Land (2016) | I17: Babylon | J17: 2022 | K17: Theatrical | L17: $78–80M | M17: $64.9M | N17: Untitled prison drama (Craig/Murphy/Williams) | O17: TBA | P17: In development (cast announced) | Q17: Limited once in production | R17: Med | S17: 4 | T17: Brad Pitt; Margot Robbie; Daniel Craig; Cillian Murphy; Michelle Williams | U17: Justin Hurwitz (music); Linus Sandgren (DP, past) | V17: Talent magnet; recent box-office miss makes lane/scale choice important. | W17: Ambitious setpieces can drive cost. | X17: 46051 | Y17: https://en.wikipedia.org/wiki/Babylon_(2022_film) | Z17: https://variety.com/2026/film/news/michelle-williams-joins-daniel-craig-cillian-murphy-damien-chazelle-movie-1236630331/ | AT17: =IFERROR(VLOOKUP(AS17,BUDGET_BANDS!$A$2:$C$9,2,FALSE),"") | AU17: =IFERROR(VLOOKUP(AS17,BUDGET_BANDS!$A$2:$C$9,3,FALSE),"")
A18: Rian Johnson | B18: T1 | C18: Established (franchise + original) | D18: Mystery / thriller | E18: Sci-fi | F18: $40M–$150M | G18: Playful whodunnit mechanics, twisty | H18: Wake Up Dead Man (2025); Glass Onion (2022); The Last Jedi (2017) | I18: Wake Up Dead Man | J18: 2025 | K18: Streamer (Netflix) | L18: $151.7M | M18: $2.5M (limited theatrical) | N18: TBA (post Netflix deal) | P18: TBD | Q18: Unknown | R18: Low | S18: 4 | T18: Daniel Craig; Josh O'Connor; Glenn Close; Josh Brolin | U18: Ram Bergman (prod); Netflix (Knives Out deal) | V18: Can package ensemble; strong with stars in mystery lane. | W18: Schedules often flexible but dependent on streamer deals. | X18: 46051 | Y18: https://en.wikipedia.org/wiki/Wake_Up_Dead_Man | AT18: =IFERROR(VLOOKUP(AS18,BUDGET_BANDS!$A$2:$C$9,2,FALSE),"") | AU18: =IFERROR(VLOOKUP(AS18,BUDGET_BANDS!$A$2:$C$9,3,FALSE),"")
A19: Taika Waititi | B19: T1 | C19: Established (genre + comedy) | D19: Comedy/drama with heart | E19: Fantasy/sci-fi | F19: $10M–$250M | G19: Quirky humor + emotion | H19: Next Goal Wins (2023); Thor: Love and Thunder (2022); Jojo Rabbit (2019) | I19: Next Goal Wins | J19: 2023 | K19: Theatrical | L19: $14M | M19: $18.6M | N19: Klara and the Sun | O19: 2026 (US, Sony) | P19: Announced | Q19: Limited (2026 release pipeline) | R19: Med | S19: 3 | T19: Michael Fassbender; Jenna Ortega; Amy Adams; Steve Buscemi | U19: Taika often multi-hyphen; diverse producer network | V19: Strong tone fit for offbeat/heart; can be polarizing commercially. | W19: Comedic improvisation can add takes/time. | X19: 46051 | Y19: https://en.wikipedia.org/wiki/Next_Goal_Wins_(2023_film) | Z19: https://en.wikipedia.org/wiki/Klara_and_the_Sun_(film) | AT19: =IFERROR(VLOOKUP(AS19,BUDGET_BANDS!$A$2:$C$9,2,FALSE),"") | AU19: =IFERROR(VLOOKUP(AS19,BUDGET_BANDS!$A$2:$C$9,3,FALSE),"")
A20: Sam Mendes | B20: T1 | C20: Established (prestige + franchise) | D20: Prestige drama | E20: Spy/action | F20: $30M–$250M | G20: Classical craft, emotional restraint | H20: Empire of Light (2022); 1917 (2019); Spectre (2015) | I20: Empire of Light | J20: 2022 | K20: Theatrical | N20: The Beatles – A Four-Film Cinematic Event | O20: Apr 7, 2028 (all four films) | P20: Announced / in development | Q20: Likely locked 2026–2028 | R20: Med | S20: 5 | T20: Paul Mescal; Harris Dickinson; Joseph Quinn; Barry Keoghan | U20: Neal Street; Sony; Apple Corps | V20: Massive multi-film commitment—practically unavailable. | W20: Multi-film production planning; very long horizon. | X20: 46051 | Y20: https://en.wikipedia.org/wiki/The_Beatles_%E2%80%93_A_Four-Film_Cinematic_Event | Z20: https://variety.com/2025/film/news/beatles-movies-release-dates-2028-sam-mendes-1236353434/ | AA20: https://en.wikipedia.org/wiki/Sam_Mendes | AT20: =IFERROR(VLOOKUP(AS20,BUDGET_BANDS!$A$2:$C$9,2,FALSE),"") | AU20: =IFERROR(VLOOKUP(AS20,BUDGET_BANDS!$A$2:$C$9,3,FALSE),"")
A21: Ridley Scott | B21: T0 | C21: Established (high output) | D21: Epic / historical / sci-fi | E21: Thriller | F21: $50M–$300M+ | G21: Classical spectacle, muscular drama | H21: Gladiator II (2024); Napoleon (2023); The Last Duel (2021) | I21: Gladiator II | J21: 2024 | K21: Theatrical | L21: $210M net (reported) | M21: $462.2M | N21: The Dog Stars | O21: Aug 28, 2026 (US) | P21: Scheduled | Q21: Low (continuous pipeline) | R21: Med | S21: 4 | T21: Paul Mescal; Pedro Pascal; Denzel Washington; Jacob Elordi | U21: Scott Free; frequent large-scale crews | V21: Can mount big productions; often multiple projects in flight. | W21: High output but large logistics; schedule can shift. | X21: 46051 | Y21: https://en.wikipedia.org/wiki/Gladiator_II | Z21: https://en.wikipedia.org/wiki/The_Dog_Stars_(film) | AA21: https://www.hollywoodreporter.com/movies/movie-news/box-office-ridley-scotts-the-dog-stars-pushed-1236457245/ | AT21: =IFERROR(VLOOKUP(AS21,BUDGET_BANDS!$A$2:$C$9,2,FALSE),"") | AU21: =IFERROR(VLOOKUP(AS21,BUDGET_BANDS!$A$2:$C$9,3,FALSE),"")
A22: Martin Scorsese | B22: T0 | C22: Legacy peak | D22: Crime / prestige drama | E22: Historical epic | F22: $50M–$200M | G22: Character + moral complexity | H22: Killers of the Flower Moon (2023); The Irishman (2019); Silence (2016) | I22: Killers of the Flower Moon | J22: 2023 | K22: Theatrical+streamer | L22: $200–215M | M22: $158.8M | N22: What Happens at Night | O22: TBA (filming reported Feb 2026) | P22: Announced | Q22: Limited | R22: Med | S22: 5 | T22: Leonardo DiCaprio; Robert De Niro; Jennifer Lawrence (next) | U22: DiCaprio (repeat); Thelma Schoonmaker (editor) | V22: Top prestige attachment; often talent-driven packages. | W22: Long runtimes/edits; schedule depends on lead talent. | X22: 46051 | Y22: https://en.wikipedia.org/wiki/Killers_of_the_Flower_Moon_(film) | Z22: https://deadline.com/2025/09/scorsese-dicaprio-jennifer-lawrence-what-happens-at-night-1236548458/ | AT22: =IFERROR(VLOOKUP(AS22,BUDGET_BANDS!$A$2:$C$9,2,FALSE),"") | AU22: =IFERROR(VLOOKUP(AS22,BUDGET_BANDS!$A$2:$C$9,3,FALSE),"")
A23: Guillermo del Toro | B23: T1 | C23: Established (auteur + studio) | D23: Fantasy / gothic | E23: Drama, horror | F23: $30M–$120M | G23: Gothic emotion, creature design | H23: Frankenstein (2025); Pinocchio (2022); Nightmare Alley (2021) | I23: Frankenstein | J23: 2025 | K23: Streamer (Netflix) | L23: $120M | M23: (mostly streaming; limited BO) | N23: TBA | P23: TBD | Q23: Unknown | R23: Low | S23: 4 | T23: Oscar Isaac; Jacob Elordi; Mia Goth; Christoph Waltz | U23: Dan Laustsen (DP); Netflix (recent) | V23: Strong for elevated genre and awards lane; streamer relationships matter. | W23: Design-heavy; long preproduction. | X23: 46051 | Y23: https://en.wikipedia.org/wiki/Frankenstein_(2025_film) | Z23: https://www.netflix.com/title/81507921 | AT23: =IFERROR(VLOOKUP(AS23,BUDGET_BANDS!$A$2:$C$9,2,FALSE),"") | AU23: =IFERROR(VLOOKUP(AS23,BUDGET_BANDS!$A$2:$C$9,3,FALSE),"")
A24: Bong Joon Ho | B24: T1 | C24: Established (international event auteur) | D24: Satirical genre blends | E24: Sci-fi, thriller | F24: $30M–$120M | G24: Dark humor, class politics, tonal pivots | H24: Mickey 17 (2025); Parasite (2019); Okja (2017) | I24: Mickey 17 | J24: 2025 | K24: Theatrical | L24: $118M | M24: $133.3M | N24: Untitled animated film (in progress) | O24: ~2027 (reported update) | P24: In development/production (reported) | Q24: Low | R24: Low | S24: 4 | T24: Robert Pattinson; Naomi Ackie; Steven Yeun; Mark Ruffalo | U24: Plan B (prod, Mickey 17) | V24: High prestige; language/market considerations; next project long-horizon. | W24: Complex VFX and post cycles. | X24: 46051 | Y24: https://en.wikipedia.org/wiki/Mickey_17 | Z24: https://deadline.com/2025/11/bong-joon-ho-upcoming-animation-very-wild-tough-job-1236631084/ | AT24: =IFERROR(VLOOKUP(AS24,BUDGET_BANDS!$A$2:$C$9,2,FALSE),"") | AU24: =IFERROR(VLOOKUP(AS24,BUDGET_BANDS!$A$2:$C$9,3,FALSE),"")
A25: Chloé Zhao | B25: T2 | C25: Prestige (selective) | D25: Intimate drama | E25: Historical | F25: $10M–$60M | G25: Naturalism, lyricism | H25: Hamnet (2025); Eternals (2021); Nomadland (2020) | I25: Hamnet | J25: 2025 | K25: Theatrical | L25: $30–35M | M25: $43M | N25: TBA | P25: TBD | Q25: Unknown | R25: Low | S25: 3 | T25: Jessie Buckley; Paul Mescal; Emily Watson | U25: Focus Features (dist, Hamnet) | V25: Strong awards lane attachment; not a commercial genre lever. | W25: Often location/available-light oriented. | X25: 46051 | Y25: https://en.wikipedia.org/wiki/Hamnet_(film) | Z25: https://www.hollywoodreporter.com/movies/movie-news/chloe-zhao-hamnet-bafta-most-nominated-film-female-director-1236485900/ | AT25: =IFERROR(VLOOKUP(AS25,BUDGET_BANDS!$A$2:$C$9,2,FALSE),"") | AU25: =IFERROR(VLOOKUP(AS25,BUDGET_BANDS!$A$2:$C$9,3,FALSE),"")
A26: Barry Jenkins | B26: T1 | C26: Peak (prestige + Disney scale) | D26: Character drama | E26: Family musical (CG), sci-fi thriller (next) | F26: $30M–$200M | G26: Emotional intimacy, lyrical imagery | H26: Mufasa: The Lion King (2024); If Beale Street Could Talk (2018); Moonlight (2016) | I26: Mufasa: The Lion King | J26: 2024 | K26: Theatrical | L26: $200M | M26: $723M | N26: The Natural Order | O26: TBA | P26: In talks / announced package | Q26: Unknown | R26: Low | S26: 4 | T26: Aaron Pierre; Kelvin Harrison Jr.; Glen Powell (next) | U26: Adele Romanski (prod, past); Universal (next package) | V26: Can bridge prestige to commercial; actors respond. | W26: Lane varies widely depending on project scale. | X26: 46051 | Y26: https://en.wikipedia.org/wiki/Mufasa:_The_Lion_King | Z26: https://deadline.com/2025/03/glen-powell-barry-jenkins-the-natural-order-movie-1236324474/ | AT26: =IFERROR(VLOOKUP(AS26,BUDGET_BANDS!$A$2:$C$9,2,FALSE),"") | AU26: =IFERROR(VLOOKUP(AS26,BUDGET_BANDS!$A$2:$C$9,3,FALSE),"")
A27: Steve McQueen | B27: T2 | C27: Prestige (selective) | D27: Historical drama | E27: Thriller | F27: $10M–$80M | G27: Formally rigorous, intense | H27: Blitz (2024); Widows (2018); 12 Years a Slave (2013) | I27: Blitz | J27: 2024 | K27: Streamer (Apple TV+) | N27: TBA | P27: TBD | Q27: Unknown | R27: Low | S27: 3 | T27: Saoirse Ronan; Harris Dickinson; Stephen Graham | U27: Working Title / Apple (Blitz) | V27: Awards/prestige lever. | W27: Often formal approach; production depends on partners. | X27: 46051 | Y27: https://en.wikipedia.org/wiki/Blitz_(2024_film) | AT27: =IFERROR(VLOOKUP(AS27,BUDGET_BANDS!$A$2:$C$9,2,FALSE),"") | AU27: =IFERROR(VLOOKUP(AS27,BUDGET_BANDS!$A$2:$C$9,3,FALSE),"")
A28: Emerald Fennell | B28: T2 | C28: Hot | D28: Dark comedy / provocative drama | E28: Period romance | F28: $10M–$60M | G28: Satirical, edgy, stylized | H28: Saltburn (2023); Promising Young Woman (2020); (shorts/TV prior) | I28: Saltburn | J28: 2023 | K28: Streamer + limited theatrical | M28: $21.1M | N28: Wuthering Heights | O28: Feb 13, 2026 | P28: Releasing | Q28: Likely unavailable until after Feb 2026 release | R28: Med | S28: 4 | T28: Barry Keoghan; Jacob Elordi; Margot Robbie (prod/star) | U28: LuckyChap (prod); Jacob Elordi (repeat) | V28: Tone-specific; can attract buzzy casts. | W28: Content can be polarizing; marketing sensitive. | X28: 46051 | Y28: https://en.wikipedia.org/wiki/Saltburn_(film) | Z28: https://people.com/all-about-wuthering-heights-movie-11891199 | AT28: =IFERROR(VLOOKUP(AS28,BUDGET_BANDS!$A$2:$C$9,2,FALSE),"") | AU28: =IFERROR(VLOOKUP(AS28,BUDGET_BANDS!$A$2:$C$9,3,FALSE),"")
A29: Shawn Levy | B29: T0 | C29: Peak (studio event + IP) | D29: Commercial action/adventure comedy | E29: Sci-fi, franchise | F29: $100M–$250M+ | G29: Big-hearted crowd-pleaser | H29: Deadpool & Wolverine (2024); The Adam Project (2022); Free Guy (2021) | I29: Deadpool & Wolverine | J29: 2024 | K29: Theatrical | L29: (see source) | M29: $1.338B | N29: Star Wars: Starfighter | O29: May 28, 2027 | P29: Post-production (filming wrapped Dec 2025) | Q29: Low (post + follow-ups) | R29: Med | S29: 5 | T29: Ryan Reynolds; Hugh Jackman; Ryan Gosling (Starfighter) | U29: 21 Laps; Ryan Reynolds (repeat) | V29: Top-tier commercial attachment; schedule tied to SW post pipeline. | W29: Large VFX post; Disney/Lucasfilm process. | X29: 46051 | Y29: https://en.wikipedia.org/wiki/Deadpool_%26_Wolverine | Z29: https://en.wikipedia.org/wiki/Star_Wars:_Starfighter | AA29: https://people.com/starfighter-writer-teases-star-wars-movie-with-ryan-gosling-exclusive-11889140 | AT29: =IFERROR(VLOOKUP(AS29,BUDGET_BANDS!$A$2:$C$9,2,FALSE),"") | AU29: =IFERROR(VLOOKUP(AS29,BUDGET_BANDS!$A$2:$C$9,3,FALSE),"")
A30: Paul King | B30: T1 | C30: Hot (family musical hit) | D30: Family / comedy | E30: Musical fantasy | F30: $50M–$150M | G30: Warmth, whimsy, precision comedy | H30: Wonka (2023); Paddington 2 (2017); Paddington (2014) | I30: Wonka | J30: 2023 | K30: Theatrical | L30: $125M | M30: $634.5M | N30: Labubu (Sony) | O30: TBA | P30: Early development (announced) | Q30: Unknown | R30: Low | S30: 4 | T30: Timothée Chalamet; Olivia Colman; Hugh Grant | U30: Heyday Films (prod); Warner Bros (Wonka) | V30: Very strong for family lane; reliable tone control. | W30: Family brand alignment important. | X30: 46051 | Y30: https://en.wikipedia.org/wiki/Wonka_(film) | Z30: https://variety.com/2025/film/news/labubu-movie-wonka-paddington-director-paul-king-1236612320/ | AA30: https://www.hollywoodreporter.com/movies/movie-news/paul-king-to-direct-labubu-movie-for-sony-1236453921/ | AT30: =IFERROR(VLOOKUP(AS30,BUDGET_BANDS!$A$2:$C$9,2,FALSE),"") | AU30: =IFERROR(VLOOKUP(AS30,BUDGET_BANDS!$A$2:$C$9,3,FALSE),"")
A31: Patty Jenkins | B31: T1 | C31: Established (big IP) | D31: Superhero / action | E31: Drama | F31: $50M–$200M | G31: Earnest heroism, classical arcs | H31: Wonder Woman 1984 (2020); Wonder Woman (2017); Monster (2003) | I31: Wonder Woman 1984 | J31: 2020 | K31: Theatrical+HBO Max (pandemic) | L31: $200M | M31: $169.6M | N31: Rogue Squadron (status uncertain) / TBA | O31: TBA | P31: Reported / unconfirmed by Lucasfilm | Q31: Unknown | R31: Low | S31: 3 | T31: Gal Gadot; Chris Pine; Kristen Wiig; Pedro Pascal | U31: Warner/DC (past) | V31: Action/hero lane; next project status needs verification. | W31: Big studio processes; schedule dependent on greenlight. | X31: 46051 | Y31: https://en.wikipedia.org/wiki/Wonder_Woman_1984 | Z31: https://editorial.rottentomatoes.com/article/every-upcoming-star-wars-movie-and-series-with-key-details-and-dates/ | AA31: https://www.the-numbers.com/person/761230401-Patty-Jenkins | AT31: =IFERROR(VLOOKUP(AS31,BUDGET_BANDS!$A$2:$C$9,2,FALSE),"") | AU31: =IFERROR(VLOOKUP(AS31,BUDGET_BANDS!$A$2:$C$9,3,FALSE),"")

Sheet UNIVERSE
A1: Director | B1: Tier | C1: CareerPhase | D1: Region | E1: PrimaryLane | F1: SecondaryLanes | G1: ScaleProven | H1: TonalDNA | I1: Last3Features | J1: LastFilm | K1: LastFilmYear | L1: LastFilmType | M1: NextProject | N1: NextStatus | O1: ActorMagnet | P1: PackagingNotes | Q1: OpsNotes | R1: ResearchStatus | S1: SeededOn | T1: WikipediaSearch | U1: IMDbSearch | V1: TheNumbersURL | W1: Last3_Source | X1: Film1_Title | Y1: Film1_ReleaseDate | Z1: Film1_DomesticGrossUSD | AA1: Film1_IntlGrossUSD | AB1: Film1_WWGrossUSD | AC1: Film2_Title | AD1: Film2_ReleaseDate | AE1: Film2_DomesticGrossUSD | AF1: Film2_IntlGrossUSD | AG1: Film2_WWGrossUSD | AH1: Film3_Title | AI1: Film3_ReleaseDate | AJ1: Film3_DomesticGrossUSD | AK1: Film3_IntlGrossUSD | AL1: Film3_WWGrossUSD | AM1: LastFilmWWGrossUSD | AN1: BudgetBandTypical | AO1: BudgetBandLowUSD | AP1: BudgetBandHighUSD
A2: Christopher Nolan | B2: T0 | C2: Peak (Event filmmaker) | E2: Epic drama / high-concept spectacle | F2: Historical, thriller | G2: $100M–$250M+ | H2: Precision, IMAX spectacle, time/structure games | I2: Oppenheimer (2023); Tenet (2020); Dunkirk (2017) | J2: Oppenheimer | K2: 2023 | L2: Theatrical | M2: The Odyssey | N2: Post-production/announced release | O2: 5 | P2: Can attract A-list and premium formats; schedule locked to July 2026 release. | Q2: Long prep/post; prefers high control and specific formats. | R2: In TOP sheet | S2: 2026-01-29 | T2: https://en.wikipedia.org/w/index.php?search=Christopher+Nolan | U2: https://www.imdb.com/find/?q=Christopher+Nolan&s=nm | V2: https://www.the-numbers.com/person/106410401-Christopher-Nolan | W2: The Numbers | X2: Oppenheimer | Y2: Jul 21, 2023 | Z2: 330078895 | AA2: 646678360 | AB2: 976757255 | AC2: Tenet | AD2: Sep 3, 2020 | AE2: 59473550 | AF2: 306800000 | AG2: 366273550 | AH2: Dunkirk | AI2: Jul 21, 2017 | AJ2: 190068280 | AK2: 338000000 | AL2: 528068280 | AM2: 976757255 | AO2: =IFERROR(VLOOKUP(AN2,BUDGET_BANDS!$A$2:$C$9,2,FALSE),"") | AP2: =IFERROR(VLOOKUP(AN2,BUDGET_BANDS!$A$2:$C$9,3,FALSE),"")
A3: Denis Villeneuve | B3: T0 | C3: Peak (Prestige + tentpole) | E3: Sci-fi / epic worldbuilding | F3: Thriller, drama | G3: $100M–$200M+ | H3: Atmospheric, austere, grounded scale | I3: Dune: Part Two (2024); Dune (2021); Blade Runner 2049 (2017) | J3: Dune: Part Two | K3: 2024 | L3: Theatrical | M3: James Bond (next film) / Dune: Part Three | N3: Announced / in development | O3: 5 | P3: Bankable for elevated sci-fi/action; high studio alignment; schedule likely locked. | Q3: Large-scale VFX and long post cycles common. | R3: In TOP sheet | S3: 2026-01-29 | T3: https://en.wikipedia.org/w/index.php?search=Denis+Villeneuve | U3: https://www.imdb.com/find/?q=Denis+Villeneuve&s=nm | V3: https://www.the-numbers.com/person/447440401-Denis-Villeneuve | W3: The Numbers | X3: Dune: Part Two | Y3: Mar 1, 2024 | Z3: 282709065 | AA3: 432497130 | AB3: 715206195 | AC3: Dune | AD3: Oct 22, 2021 | AE3: 111031267 | AF3: 318518799 | AG3: 429550066 | AH3: Blade Runner 2049 | AI3: Oct 6, 2017 | AJ3: 92054159 | AK3: 167100000 | AL3: 259154159 | AM3: 715206195 | AO3: =IFERROR(VLOOKUP(AN3,BUDGET_BANDS!$A$2:$C$9,2,FALSE),"") | AP3: =IFERROR(VLOOKUP(AN3,BUDGET_BANDS!$A$2:$C$9,3,FALSE),"")
A4: Greta Gerwig | B4: T0 | C4: Peak (IP + auteur) | E4: Comedy/drama with strong voice; IP reinvention | F4: Fantasy | G4: $50M–$200M | H4: Character-forward, witty, empathetic | I4: Barbie (2023); Little Women (2019); Lady Bird (2017) | J4: Barbie | K4: 2023 | L4: Theatrical | M4: Narnia: The Magician's Nephew | N4: Announced / pre-production | O4: 5 | P4: Strong actor/brand magnet; lanes beyond comedy now include big fantasy. | Q4: Likely high creative control; talent-heavy ensembles. | R4: In TOP sheet | S4: 2026-01-29 | T4: https://en.wikipedia.org/w/index.php?search=Greta+Gerwig | U4: https://www.imdb.com/find/?q=Greta+Gerwig&s=nm | V4: https://www.the-numbers.com/person/54050401-Greta-Gerwig | W4: The Numbers | X4: Barbie | Y4: Jul 21, 2023 | Z4: 636785476 | AA4: 810900000 | AB4: 1447685476 | AC4: Little Women | AD4: Dec 25, 2019 | AE4: 108095955 | AF4: 110742431 | AG4: 218838386 | AH4: Lady Bird | AI4: Nov 3, 2017 | AJ4: 48958273 | AK4: 31150209 | AL4: 80108482 | AM4: 1447685476 | AO4: =IFERROR(VLOOKUP(AN4,BUDGET_BANDS!$A$2:$C$9,2,FALSE),"") | AP4: =IFERROR(VLOOKUP(AN4,BUDGET_BANDS!$A$2:$C$9,3,FALSE),"")
A5: James Gunn | B5: T0 | C5: Peak (franchise architect + director) | E5: Superhero / big ensemble action-comedy | F5: Genre comedy | G5: $150M–$225M+ | H5: Heart + humor, weirdness, ensemble dynamics | I5: Superman (2025); Guardians of the Galaxy Vol 3 (2023); The Suicide Squad (2021) | J5: Superman | K5: 2025 | L5: Theatrical | M5: Man of Tomorrow (Super-Family follow-up) | N5: Announced / in development | O5: 5 | P5: Extremely strong studio leverage; schedule largely committed. | Q5: Runs studio + directs—availability is the bottleneck. | R5: In TOP sheet | S5: 2026-01-29 | T5: https://en.wikipedia.org/w/index.php?search=James+Gunn | U5: https://www.imdb.com/find/?q=James+Gunn&s=nm | V5: https://www.the-numbers.com/person/59460401-James-Gunn | W5: The Numbers | X5: Superman | Y5: Jul 11, 2025 | Z5: 354223803 | AA5: 262600000 | AB5: 616823803 | AC5: Guardians of the Galaxy Vol 3 | AD5: May 5, 2023 | AE5: 358995815 | AF5: 486559962 | AG5: 845555777 | AH5: The Suicide Squad | AI5: Aug 5, 2021 | AJ5: 55817425 | AK5: 112900000 | AL5: 168717425 | AM5: 616823803 | AO5: =IFERROR(VLOOKUP(AN5,BUDGET_BANDS!$A$2:$C$9,2,FALSE),"") | AP5: =IFERROR(VLOOKUP(AN5,BUDGET_BANDS!$A$2:$C$9,3,FALSE),"")
A6: Martin Scorsese | B6: T0 | C6: Legacy peak | E6: Crime / prestige drama | F6: Historical epic | G6: $50M–$200M | H6: Character + moral complexity | I6: Killers of the Flower Moon (2023); The Irishman (2019); Silence (2016) | J6: Killers of the Flower Moon | K6: 2023 | L6: Theatrical+streamer | M6: What Happens at Night | N6: Announced | O6: 5 | P6: Top prestige attachment; often talent-driven packages. | Q6: Long runtimes/edits; schedule depends on lead talent. | R6: In TOP sheet | S6: 2026-01-29 | T6: https://en.wikipedia.org/w/index.php?search=Martin+Scorsese | U6: https://www.imdb.com/find/?q=Martin+Scorsese&s=nm | AO6: =IFERROR(VLOOKUP(AN6,BUDGET_BANDS!$A$2:$C$9,2,FALSE),"") | AP6: =IFERROR(VLOOKUP(AN6,BUDGET_BANDS!$A$2:$C$9,3,FALSE),"")
A7: Matt Reeves | B7: T0 | C7: Peak (franchise + auteur) | E7: Dark franchise thriller | F7: Sci-fi, drama | G7: $100M–$200M | H7: Noir mood, grounded intensity | I7: The Batman (2022); War for the Planet of the Apes (2017); Dawn of the Planet of the Apes (2014) | J7: The Batman | K7: 2022 | L7: Theatrical | M7: The Batman: Part II | N7: Announced; filming spring 2026 (reported) | O7: 4 | P7: Strong tonal franchise; likely unavailable through production. | Q7: Long dev cycles; careful worldbuilding. | R7: In TOP sheet | S7: 2026-01-29 | T7: https://en.wikipedia.org/w/index.php?search=Matt+Reeves | U7: https://www.imdb.com/find/?q=Matt+Reeves&s=nm | AO7: =IFERROR(VLOOKUP(AN7,BUDGET_BANDS!$A$2:$C$9,2,FALSE),"") | AP7: =IFERROR(VLOOKUP(AN7,BUDGET_BANDS!$A$2:$C$9,3,FALSE),"")
A8: Ridley Scott | B8: T0 | C8: Established (high output) | E8: Epic / historical / sci-fi | F8: Thriller | G8: $50M–$300M+ | H8: Classical spectacle, muscular drama | I8: Gladiator II (2024); Napoleon (2023); The Last Duel (2021) | J8: Gladiator II | K8: 2024 | L8: Theatrical | M8: The Dog Stars | N8: Scheduled | O8: 4 | P8: Can mount big productions; often multiple projects in flight. | Q8: High output but large logistics; schedule can shift. | R8: In TOP sheet | S8: 2026-01-29 | T8: https://en.wikipedia.org/w/index.php?search=Ridley+Scott | U8: https://www.imdb.com/find/?q=Ridley+Scott&s=nm | AO8: =IFERROR(VLOOKUP(AN8,BUDGET_BANDS!$A$2:$C$9,2,FALSE),"") | AP8: =IFERROR(VLOOKUP(AN8,BUDGET_BANDS!$A$2:$C$9,3,FALSE),"")
A9: Shawn Levy | B9: T0 | C9: Peak (studio event + IP) | E9: Commercial action/adventure comedy | F9: Sci-fi, franchise | G9: $100M–$250M+ | H9: Big-hearted crowd-pleaser | I9: Deadpool & Wolverine (2024); The Adam Project (2022); Free Guy (2021) | J9: Deadpool & Wolverine | K9: 2024 | L9: Theatrical | M9: Star Wars: Starfighter | N9: Post-production (filming wrapped Dec 2025) | O9: 5 | P9: Top-tier commercial attachment; schedule tied to SW post pipeline. | Q9: Large VFX post; Disney/Lucasfilm process. | R9: In TOP sheet | S9: 2026-01-29 | T9: https://en.wikipedia.org/w/index.php?search=Shawn+Levy | U9: https://www.imdb.com/find/?q=Shawn+Levy&s=nm | AO9: =IFERROR(VLOOKUP(AN9,BUDGET_BANDS!$A$2:$C$9,2,FALSE),"") | AP9: =IFERROR(VLOOKUP(AN9,BUDGET_BANDS!$A$2:$C$9,3,FALSE),"")
A10: Barry Jenkins | B10: T1 | C10: Peak (prestige + Disney scale) | E10: Character drama | F10: Family musical (CG), sci-fi thriller (next) | G10: $30M–$200M | H10: Emotional intimacy, lyrical imagery | I10: Mufasa: The Lion King (2024); If Beale Street Could Talk (2018); Moonlight (2016) | J10: Mufasa: The Lion King | K10: 2024 | L10: Theatrical | M10: The Natural Order | N10: In talks / announced package | O10: 4 | P10: Can bridge prestige to commercial; actors respond. | Q10: Lane varies widely depending on project scale. | R10: In TOP sheet | S10: 2026-01-29 | T10: https://en.wikipedia.org/w/index.php?search=Barry+Jenkins | U10: https://www.imdb.com/find/?q=Barry+Jenkins&s=nm | AO10: =IFERROR(VLOOKUP(AN10,BUDGET_BANDS!$A$2:$C$9,2,FALSE),"") | AP10: =IFERROR(VLOOKUP(AN10,BUDGET_BANDS!$A$2:$C$9,3,FALSE),"")
A11: Bong Joon Ho | B11: T1 | C11: Established (international event auteur) | E11: Satirical genre blends | F11: Sci-fi, thriller | G11: $30M–$120M | H11: Dark humor, class politics, tonal pivots | I11: Mickey 17 (2025); Parasite (2019); Okja (2017) | J11: Mickey 17 | K11: 2025 | L11: Theatrical | M11: Untitled animated film (in progress) | N11: In development/production (reported) | O11: 4 | P11: High prestige; language/market considerations; next project long-horizon. | Q11: Complex VFX and post cycles. | R11: In TOP sheet | S11: 2026-01-29 | T11: https://en.wikipedia.org/w/index.php?search=Bong+Joon+Ho | U11: https://www.imdb.com/find/?q=Bong+Joon+Ho&s=nm | AO11: =IFERROR(VLOOKUP(AN11,BUDGET_BANDS!$A$2:$C$9,2,FALSE),"") | AP11: =IFERROR(VLOOKUP(AN11,BUDGET_BANDS!$A$2:$C$9,3,FALSE),"")
A12: Chad Stahelski | B12: T1 | C12: Peak (action franchise builder) | E12: Action (stunt-driven) | F12: Thriller | G12: $50M–$120M+ | H12: Choreography-forward, clean mythic action | I12: John Wick: Chapter 4 (2023); John Wick: Chapter 3 (2019); John Wick: Chapter 2 (2017) | J12: John Wick: Chapter 4 | K12: 2023 | L12: Theatrical | M12: Highlander | N12: Announced / in development | O12: 3 | P12: Great for action lane matching; tends toward long prep for choreography. | Q12: Action-heavy prep, stunt safety, extended unit work. | R12: In TOP sheet | S12: 2026-01-29 | T12: https://en.wikipedia.org/w/index.php?search=Chad+Stahelski | U12: https://www.imdb.com/find/?q=Chad+Stahelski&s=nm | AO12: =IFERROR(VLOOKUP(AN12,BUDGET_BANDS!$A$2:$C$9,2,FALSE),"") | AP12: =IFERROR(VLOOKUP(AN12,BUDGET_BANDS!$A$2:$C$9,3,FALSE),"")
A13: Christopher McQuarrie | B13: T1 | C13: Peak (action specialist) | E13: High-end action / spy | F13: Thriller | G13: $150M–$400M | H13: Practical stunt spectacle, precision pacing | I13: Mission: Impossible – The Final Reckoning (2025); Dead Reckoning (2023); Fallout (2018) | J13: Mission: Impossible – The Final Reckoning | K13: 2025 | L13: Theatrical | M13: (TBA) likely action package(s) | N13: TBD | O13: 4 | P13: Elite action credibility; availability depends on next Cruise/Paramount commitments. | Q13: Complex stunts can extend schedules. | R13: In TOP sheet | S13: 2026-01-29 | T13: https://en.wikipedia.org/w/index.php?search=Christopher+McQuarrie | U13: https://www.imdb.com/find/?q=Christopher+McQuarrie&s=nm | AO13: =IFERROR(VLOOKUP(AN13,BUDGET_BANDS!$A$2:$C$9,2,FALSE),"") | AP13: =IFERROR(VLOOKUP(AN13,BUDGET_BANDS!$A$2:$C$9,3,FALSE),"")
A14: David Fincher | B14: T1 | C14: Established | D14: US/Intl | E14: Thriller/Mystery | F14: Crime/Heist,Drama | G14: Studio/Mid | H14: tense, precise | R14: Seeded | S14: 2026-01-29 | T14: https://en.wikipedia.org/w/index.php?search=David+Fincher | U14: https://www.imdb.com/find/?q=David+Fincher&s=nm | AO14: =IFERROR(VLOOKUP(AN14,BUDGET_BANDS!$A$2:$C$9,2,FALSE),"") | AP14: =IFERROR(VLOOKUP(AN14,BUDGET_BANDS!$A$2:$C$9,3,FALSE),"")
A15: David Leitch | B15: T1 | C15: Hot (studio action-comedy) | E15: Action-comedy | F15: Thriller | G15: $80M–$150M | H15: Stunts + humor, pop energy | I15: The Fall Guy (2024); Bullet Train (2022); Hobbs & Shaw (2019) | J15: The Fall Guy | K15: 2024 | L15: Theatrical | M15: How to Rob a Bank | N15: In development | O15: 4 | P15: Good for action+comedy scripts; can attract major stars. | Q15: High stunt needs; can run parallel units. | R15: In TOP sheet | S15: 2026-01-29 | T15: https://en.wikipedia.org/w/index.php?search=David+Leitch | U15: https://www.imdb.com/find/?q=David+Leitch&s=nm | AO15: =IFERROR(VLOOKUP(AN15,BUDGET_BANDS!$A$2:$C$9,2,FALSE),"") | AP15: =IFERROR(VLOOKUP(AN15,BUDGET_BANDS!$A$2:$C$9,3,FALSE),"")
A16: Guillermo del Toro | B16: T1 | C16: Established (auteur + studio) | E16: Fantasy / gothic | F16: Drama, horror | G16: $30M–$120M | H16: Gothic emotion, creature design | I16: Frankenstein (2025); Pinocchio (2022); Nightmare Alley (2021) | J16: Frankenstein | K16: 2025 | L16: Streamer (Netflix) | M16: TBA | N16: TBD | O16: 4 | P16: Strong for elevated genre and awards lane; streamer relationships matter. | Q16: Design-heavy; long preproduction. | R16: In TOP sheet | S16: 2026-01-29 | T16: https://en.wikipedia.org/w/index.php?search=Guillermo+del+Toro | U16: https://www.imdb.com/find/?q=Guillermo+del+Toro&s=nm | AO16: =IFERROR(VLOOKUP(AN16,BUDGET_BANDS!$A$2:$C$9,2,FALSE),"") | AP16: =IFERROR(VLOOKUP(AN16,BUDGET_BANDS!$A$2:$C$9,3,FALSE),"")
A17: James Wan | B17: T1 | C17: Established (franchise horror + superhero) | E17: Horror / supernatural | F17: Superhero action | G17: $20M–$215M | H17: Tension craft, genre mechanics | I17: Aquaman and the Lost Kingdom (2023); Malignant (2021); Aquaman (2018) | J17: Aquaman and the Lost Kingdom | K17: 2023 | L17: Theatrical | M17: TBD (producer-heavy slate) | N17: TBD | O17: 3 | P17: Strong for horror lane; director availability uncertain. | Q17: Often producing multiple projects concurrently. | R17: In TOP sheet | S17: 2026-01-29 | T17: https://en.wikipedia.org/w/index.php?search=James+Wan | U17: https://www.imdb.com/find/?q=James+Wan&s=nm | V17: https://www.the-numbers.com/person/148690401-James-Wan | W17: The Numbers | X17: Aquaman and the Lost Kingdom | Y17: Dec 22, 2023 | Z17: 124481226 | AA17: 315700000 | AB17: 440181226 | AC17: Malignant | AD17: Sep 10, 2021 | AE17: 13391791 | AF17: 21500000 | AG17: 34891791 | AH17: Aquaman | AI17: Dec 21, 2018 | AJ17: 335061807 | AK17: 813800000 | AL17: 1148861807 | AM17: 440181226 | AO17: =IFERROR(VLOOKUP(AN17,BUDGET_BANDS!$A$2:$C$9,2,FALSE),"") | AP17: =IFERROR(VLOOKUP(AN17,BUDGET_BANDS!$A$2:$C$9,3,FALSE),"")
A18: Jordan Peele | B18: T1 | C18: Selective (event horror auteur) | E18: Social horror / thriller | F18: Sci-fi | G18: $10M–$70M | H18: High concept, uneasy humor, thematic metaphor | I18: Nope (2022); Us (2019); Get Out (2017) | J18: Nope | K18: 2022 | L18: Theatrical | M18: Untitled next feature (Universal) – release date removed | N18: In development | O18: 4 | P18: High-value attachment for horror/thriller; scarcity increases leverage. | Q18: Typically original scripts with secrecy; controlled info flow. | R18: In TOP sheet | S18: 2026-01-29 | T18: https://en.wikipedia.org/w/index.php?search=Jordan+Peele | U18: https://www.imdb.com/find/?q=Jordan+Peele&s=nm | AO18: =IFERROR(VLOOKUP(AN18,BUDGET_BANDS!$A$2:$C$9,2,FALSE),"") | AP18: =IFERROR(VLOOKUP(AN18,BUDGET_BANDS!$A$2:$C$9,3,FALSE),"")
A19: Joseph Kosinski | B19: T1 | C19: Hot (premium commercial) | E19: High-end commercial spectacle | F19: Sci-fi | G19: $150M–$300M | H19: Sleek realism, technical setpieces | I19: F1 (2025); Top Gun: Maverick (2022); Oblivion (2013) | J19: F1 (F1: The Movie) | K19: 2025 | L19: Theatrical | M19: Untitled UFO conspiracy thriller (Apple) | N19: Package landed at Apple (announced) | O19: 4 | P19: Strong for big-scale thrills; tends to require technical prep. | Q19: Complex production logistics; premium format pipelines. | R19: In TOP sheet | S19: 2026-01-29 | T19: https://en.wikipedia.org/w/index.php?search=Joseph+Kosinski | U19: https://www.imdb.com/find/?q=Joseph+Kosinski&s=nm | AO19: =IFERROR(VLOOKUP(AN19,BUDGET_BANDS!$A$2:$C$9,2,FALSE),"") | AP19: =IFERROR(VLOOKUP(AN19,BUDGET_BANDS!$A$2:$C$9,3,FALSE),"")
A20: M. Night Shyamalan | B20: T1 | C20: Established | D20: US/Intl | E20: Thriller/Mystery | F20: Crime/Heist,Drama | G20: Studio/Mid | H20: tense, precise | R20: Seeded | S20: 2026-01-29 | T20: https://en.wikipedia.org/w/index.php?search=M.+Night+Shyamalan | U20: https://www.imdb.com/find/?q=M.+Night+Shyamalan&s=nm | AO20: =IFERROR(VLOOKUP(AN20,BUDGET_BANDS!$A$2:$C$9,2,FALSE),"") | AP20: =IFERROR(VLOOKUP(AN20,BUDGET_BANDS!$A$2:$C$9,3,FALSE),"")
A21: Patty Jenkins | B21: T1 | C21: Established (big IP) | E21: Superhero / action | F21: Drama | G21: $50M–$200M | H21: Earnest heroism, classical arcs | I21: Wonder Woman 1984 (2020); Wonder Woman (2017); Monster (2003) | J21: Wonder Woman 1984 | K21: 2020 | L21: Theatrical+HBO Max (pandemic) | M21: Rogue Squadron (status uncertain) / TBA | N21: Reported / unconfirmed by Lucasfilm | O21: 3 | P21: Action/hero lane; next project status needs verification. | Q21: Big studio processes; schedule dependent on greenlight. | R21: In TOP sheet | S21: 2026-01-29 | T21: https://en.wikipedia.org/w/index.php?search=Patty+Jenkins | U21: https://www.imdb.com/find/?q=Patty+Jenkins&s=nm | AO21: =IFERROR(VLOOKUP(AN21,BUDGET_BANDS!$A$2:$C$9,2,FALSE),"") | AP21: =IFERROR(VLOOKUP(AN21,BUDGET_BANDS!$A$2:$C$9,3,FALSE),"")
A22: Paul King | B22: T1 | C22: Hot (family musical hit) | E22: Family / comedy | F22: Musical fantasy | G22: $50M–$150M | H22: Warmth, whimsy, precision comedy | I22: Wonka (2023); Paddington 2 (2017); Paddington (2014) | J22: Wonka | K22: 2023 | L22: Theatrical | M22: Labubu (Sony) | N22: Early development (announced) | O22: 4 | P22: Very strong for family lane; reliable tone control. | Q22: Family brand alignment important. | R22: In TOP sheet | S22: 2026-01-29 | T22: https://en.wikipedia.org/w/index.php?search=Paul+King | U22: https://www.imdb.com/find/?q=Paul+King&s=nm | AO22: =IFERROR(VLOOKUP(AN22,BUDGET_BANDS!$A$2:$C$9,2,FALSE),"") | AP22: =IFERROR(VLOOKUP(AN22,BUDGET_BANDS!$A$2:$C$9,3,FALSE),"")
A23: Rian Johnson | B23: T1 | C23: Established (franchise + original) | E23: Mystery / thriller | F23: Sci-fi | G23: $40M–$150M | H23: Playful whodunnit mechanics, twisty | I23: Wake Up Dead Man (2025); Glass Onion (2022); The Last Jedi (2017) | J23: Wake Up Dead Man | K23: 2025 | L23: Streamer (Netflix) | M23: TBA (post Netflix deal) | N23: TBD | O23: 4 | P23: Can package ensemble; strong with stars in mystery lane. | Q23: Schedules often flexible but dependent on streamer deals. | R23: In TOP sheet | S23: 2026-01-29 | T23: https://en.wikipedia.org/w/index.php?search=Rian+Johnson | U23: https://www.imdb.com/find/?q=Rian+Johnson&s=nm | AO23: =IFERROR(VLOOKUP(AN23,BUDGET_BANDS!$A$2:$C$9,2,FALSE),"") | AP23: =IFERROR(VLOOKUP(AN23,BUDGET_BANDS!$A$2:$C$9,3,FALSE),"")
A24: Ryan Coogler | B24: T1 | C24: Peak (franchise + original) | E24: Event genre + grounded drama | F24: Action, horror | G24: $50M–$200M | H24: Emotional intensity, cultural specificity, spectacle | I24: Sinners (2025); Black Panther: Wakanda Forever (2022); Black Panther (2018) | J24: Sinners | K24: 2025 | L24: Theatrical | M24: Black Panther 3 | N24: Confirmed next film (announced) | O24: 5 | P24: Can package A-list and move studio financing; strong original credibility post-Sinners. | Q24: Often multi-hyphen (writer/director/producer). | R24: In TOP sheet | S24: 2026-01-29 | T24: https://en.wikipedia.org/w/index.php?search=Ryan+Coogler | U24: https://www.imdb.com/find/?q=Ryan+Coogler&s=nm | V24: https://www.the-numbers.com/person/339010401-Ryan-Coogler | W24: The Numbers | X24: Sinners | Y24: Apr 18, 2025 | Z24: 279989632 | AA24: 88399859 | AB24: 368389491 | AC24: Black Panther: Wakanda Forever | AD24: Nov 11, 2022 | AE24: 453829060 | AF24: 405379776 | AG24: 859208836 | AH24: Black Panther | AI24: Feb 16, 2018 | AJ24: 700059566 | AK24: 634097516 | AL24: 1334157082 | AM24: 368389491 | AO24: =IFERROR(VLOOKUP(AN24,BUDGET_BANDS!$A$2:$C$9,2,FALSE),"") | AP24: =IFERROR(VLOOKUP(AN24,BUDGET_BANDS!$A$2:$C$9,3,FALSE),"")
A25: Sam Mendes | B25: T1 | C25: Established (prestige + franchise) | E25: Prestige drama | F25: Spy/action | G25: $30M–$250M | H25: Classical craft, emotional restraint | I25: Empire of Light (2022); 1917 (2019); Spectre (2015) | J25: Empire of Light | K25: 2022 | L25: Theatrical | M25: The Beatles – A Four-Film Cinematic Event | N25: Announced / in development | O25: 5 | P25: Massive multi-film commitment—practically unavailable. | Q25: Multi-film production planning; very long horizon. | R25: In TOP sheet | S25: 2026-01-29 | T25: https://en.wikipedia.org/w/index.php?search=Sam+Mendes | U25: https://www.imdb.com/find/?q=Sam+Mendes&s=nm | AO25: =IFERROR(VLOOKUP(AN25,BUDGET_BANDS!$A$2:$C$9,2,FALSE),"") | AP25: =IFERROR(VLOOKUP(AN25,BUDGET_BANDS!$A$2:$C$9,3,FALSE),"")
A26: Steven Soderbergh | B26: T1 | C26: Established | D26: US/Intl | E26: Thriller/Mystery | F26: Crime/Heist,Drama | G26: Studio/Mid | H26: tense, precise | R26: Seeded | S26: 2026-01-29 | T26: https://en.wikipedia.org/w/index.php?search=Steven+Soderbergh | U26: https://www.imdb.com/find/?q=Steven+Soderbergh&s=nm | AO26: =IFERROR(VLOOKUP(AN26,BUDGET_BANDS!$A$2:$C$9,2,FALSE),"") | AP26: =IFERROR(VLOOKUP(AN26,BUDGET_BANDS!$A$2:$C$9,3,FALSE),"")
A27: Taika Waititi | B27: T1 | C27: Established (genre + comedy) | E27: Comedy/drama with heart | F27: Fantasy/sci-fi | G27: $10M–$250M | H27: Quirky humor + emotion | I27: Next Goal Wins (2023); Thor: Love and Thunder (2022); Jojo Rabbit (2019) | J27: Next Goal Wins | K27: 2023 | L27: Theatrical | M27: Klara and the Sun | N27: Announced | O27: 3 | P27: Strong tone fit for offbeat/heart; can be polarizing commercially. | Q27: Comedic improvisation can add takes/time. | R27: In TOP sheet | S27: 2026-01-29 | T27: https://en.wikipedia.org/w/index.php?search=Taika+Waititi | U27: https://www.imdb.com/find/?q=Taika+Waititi&s=nm | AO27: =IFERROR(VLOOKUP(AN27,BUDGET_BANDS!$A$2:$C$9,2,FALSE),"") | AP27: =IFERROR(VLOOKUP(AN27,BUDGET_BANDS!$A$2:$C$9,3,FALSE),"")
A28: Adam McKay | B28: T2 | C28: Established | D28: US/UK | E28: Comedy | F28: Action-comedy,Drama | G28: Mid/Studio | H28: comedic, commercial | R28: Seeded | S28: 2026-01-29 | T28: https://en.wikipedia.org/w/index.php?search=Adam+McKay | U28: https://www.imdb.com/find/?q=Adam+McKay&s=nm | AO28: =IFERROR(VLOOKUP(AN28,BUDGET_BANDS!$A$2:$C$9,2,FALSE),"") | AP28: =IFERROR(VLOOKUP(AN28,BUDGET_BANDS!$A$2:$C$9,3,FALSE),"")
A29: Alex Garland | B29: T2 | C29: Established | D29: US/Intl | E29: Action | F29: Thriller/Mystery,Crime/Heist | G29: Studio/Mid | H29: propulsive, commercial | R29: Seeded | S29: 2026-01-29 | T29: https://en.wikipedia.org/w/index.php?search=Alex+Garland | U29: https://www.imdb.com/find/?q=Alex+Garland&s=nm | AO29: =IFERROR(VLOOKUP(AN29,BUDGET_BANDS!$A$2:$C$9,2,FALSE),"") | AP29: =IFERROR(VLOOKUP(AN29,BUDGET_BANDS!$A$2:$C$9,3,FALSE),"")
A30: Alexander Payne | B30: T2 | C30: Established | D30: US/Intl | E30: Prestige drama | F30: Drama,Biopic,Historical/Epic | G30: Mid/Studio | H30: character-forward, cinematic | R30: Seeded | S30: 2026-01-29 | T30: https://en.wikipedia.org/w/index.php?search=Alexander+Payne | U30: https://www.imdb.com/find/?q=Alexander+Payne&s=nm | AO30: =IFERROR(VLOOKUP(AN30,BUDGET_BANDS!$A$2:$C$9,2,FALSE),"") | AP30: =IFERROR(VLOOKUP(AN30,BUDGET_BANDS!$A$2:$C$9,3,FALSE),"")
A31: Alexandre Aja | B31: T2 | C31: Established | D31: US/Intl | E31: Horror | F31: Thriller/Mystery | G31: Low/Mid/Studio | H31: tense, atmospheric | R31: Seeded | S31: 2026-01-29 | T31: https://en.wikipedia.org/w/index.php?search=Alexandre+Aja | U31: https://www.imdb.com/find/?q=Alexandre+Aja&s=nm | AO31: =IFERROR(VLOOKUP(AN31,BUDGET_BANDS!$A$2:$C$9,2,FALSE),"") | AP31: =IFERROR(VLOOKUP(AN31,BUDGET_BANDS!$A$2:$C$9,3,FALSE),"")
A32: Andrew Adamson | B32: T2 | C32: Established | D32: US/Intl | E32: Family | F32: Fantasy,Adventure,Animation | G32: Studio/Tentpole | H32: accessible, emotional | R32: Seeded | S32: 2026-01-29 | T32: https://en.wikipedia.org/w/index.php?search=Andrew+Adamson | U32: https://www.imdb.com/find/?q=Andrew+Adamson&s=nm | AO32: =IFERROR(VLOOKUP(AN32,BUDGET_BANDS!$A$2:$C$9,2,FALSE),"") | AP32: =IFERROR(VLOOKUP(AN32,BUDGET_BANDS!$A$2:$C$9,3,FALSE),"")
A33: Andrew Haigh | B33: T2 | C33: Established | D33: US/Intl | E33: Prestige drama | F33: Drama,Biopic,Historical/Epic | G33: Mid/Studio | H33: character-forward, cinematic | R33: Seeded | S33: 2026-01-29 | T33: https://en.wikipedia.org/w/index.php?search=Andrew+Haigh | U33: https://www.imdb.com/find/?q=Andrew+Haigh&s=nm | AO33: =IFERROR(VLOOKUP(AN33,BUDGET_BANDS!$A$2:$C$9,2,FALSE),"") | AP33: =IFERROR(VLOOKUP(AN33,BUDGET_BANDS!$A$2:$C$9,3,FALSE),"")
